<?xml version="1.0" ?>
<robot name="sphinx" xmlns:xacro="http://www.ros.org/wiki/xacro">
  
  <!-- Include ros_control plugin -->
  <xacro:include filename="$(find sphinx_description)/urdf/plugins/ros_control.urdf.xacro" />
  <!-- Include materials -->
  <xacro:include filename="$(find sphinx_description)/urdf/materials.urdf.xacro" />
  <!-- Include laser sensor -->
  <xacro:include filename="$(find sphinx_description)/urdf/hokuyo.urdf.xacro" />


  <!-- BASE-LINK -->
  <!--Actual body/chassis of the robot-->
  <link name="base_link">
    <inertial>
      <mass value="25"/>
      <origin xyz="0 0 0"/>
      <!--The 3x3 rotational inertia matrix. -->
      <inertia ixx="0.0282916666667" ixy="0" ixz="0" iyy="0.0282916666667" iyz="0" izz="0.05625"/>
    </inertial>
    <visual>
      <origin rpy="0 0 0" xyz="0 0 0"/>
      <geometry>
        <box size="0.4 0.3 0.005"/>
      </geometry>
      <material name="White"/>
    </visual>
    <collision>
      <origin rpy="0 0 0 " xyz="0 0 0"/>
      <geometry>
        <box size="0.4 0.3 0.005"/>
      </geometry>
    </collision>
  </link>
  <gazebo reference="base_link">
    <material>Gazebo/White</material>
    <turnGravityOff>false</turnGravityOff>
  </gazebo>
  
  <!--fb : front, back ; lr: left, right -->
  <xacro:property name="wheel_rotation" value="1.57079632679"/>
  <xacro:property name="wheel_length" value="0.02"/>
  <xacro:property name="wheel_radius" value="0.04"/>

  <link name="front_right_wheel">
    <visual>
      <origin rpy="${wheel_rotation} 0  0" xyz="0 0 0"/>
      <geometry>
        <cylinder length="${wheel_length}" radius="${wheel_radius}"/>
      </geometry>
      <material name="DarkGray"/>
    </visual>
    <collision>
      <origin rpy="${wheel_rotation} 0 0" xyz="0 0 0"/>
      <geometry>
        <cylinder length="${wheel_length}" radius="${wheel_radius}"/>
      </geometry>
    </collision>
    <inertial>
      <mass value="2"/>
      <origin xyz="0 0 0"/>
      <inertia ixx="0.00108333333333" ixy="0" ixz="0" iyy="0.00108333333333" iyz="0" izz="0.002"/>
    </inertial>
  </link>
  <gazebo reference="front_right_wheel">
    <mu1 value="1.0"/>
    <mu2 value="1.0"/>
    <kp value="10000000.0"/>
    <kd value="1.0"/>
    <fdir1 value="1 0 0"/>
    <material>Gazebo/Grey</material>
    <turnGravityOff>false</turnGravityOff>
  </gazebo>
  <joint name="front_right_wheel_joint" type="continuous">
    <parent link="base_link"/>
    <child link="front_right_wheel"/>
    <origin rpy="0 0 0" xyz=".11 0.16 0.0"/>
    <axis rpy="0  0" xyz="0 1 0"/>
    <limit effort="100" velocity="100"/>
    <joint_properties damping="0.0" friction="0.0"/>
  </joint>

  <!-- Mesh wheel -->
  <xacro:property name="wheel_mesh_path" value="package://sphinx_description/meshes/myweel.dae"/>
  <xacro:property name="wheel_mesh_rotation" value="3.14"/>
  <xacro:property name="wheel_mesh_scale" value=".05"/>
  <link name="front_right_wheel1">
      <visual>
        <origin rpy="0 0 ${wheel_mesh_rotation}" xyz="-.001 0 -.047"/>
        <geometry>
              <mesh filename="${wheel_mesh_path}" scale="${wheel_mesh_scale} ${wheel_mesh_scale} ${wheel_mesh_scale}"/>
        </geometry>
        <material name="DarkGray"/>
      </visual>
      <collision>
          <origin rpy="0 0 ${wheel_mesh_rotation}" xyz="-.001 0 -.047"/>
        <geometry>
            <mesh filename="${wheel_mesh_path}" scale="${wheel_mesh_scale} ${wheel_mesh_scale} ${wheel_mesh_scale}"/>
        </geometry>
      </collision>
      <inertial>
        <mass value="2"/>
        <origin xyz="0 0 0"/>
        <inertia ixx="0.00108333333333" ixy="0" ixz="0" iyy="0.00108333333333" iyz="0" izz="0.002"/>
      </inertial>
    </link>
    <gazebo reference="front_right_wheel1">
      <mu1 value="1.0"/>
      <mu2 value="1.0"/>
      <kp value="10000000.0"/>
      <kd value="1.0"/>
      <fdir1 value="1 0 0"/>
      <material>Gazebo/Grey</material>
      <turnGravityOff>false</turnGravityOff>
    </gazebo>
    <joint name="front_right_wheel1_joint" type="fixed">
      <parent link="front_right_wheel"/>
      <child link="front_right_wheel1"/>
    </joint>

  <!-- Transmission is important to link the joints and the controller -->
  <transmission name="front_right_wheel_joint_trans">
    <type>transmission_interface/SimpleTransmission</type>
    <joint name="front_right_wheel_joint">
        <hardwareInterface>hardware_interface/VelocityJointInterface</hardwareInterface>
      </joint>
    <actuator name="front_right_wheel_joint_motor">
      <hardwareInterface>EffortJointInterface</hardwareInterface>
      <mechanicalReduction>1</mechanicalReduction>
    </actuator>
  </transmission>

    <!--fb : front, back ; lr: left, right -->
    <link name="back_right_wheel">
      <visual>
        <origin rpy="${wheel_rotation} 0  0 " xyz="0 0 0"/>
        <geometry>
          <cylinder length="${wheel_length}" radius="${wheel_radius}"/>
        </geometry>
        <material name="DarkGray"/>
      </visual>
      <collision>
        <origin rpy="${wheel_rotation} 0 0 " xyz="0 0 0"/>
        <geometry>
          <cylinder length="${wheel_length}" radius="${wheel_radius}"/>
        </geometry>
      </collision>
      <inertial>
        <mass value="2"/>
        <origin xyz="0 0 0"/>
        <inertia ixx="0.00108333333333" ixy="0" ixz="0" iyy="0.00108333333333" iyz="0" izz="0.002"/>
      </inertial>
    </link>
    <gazebo reference="back_right_wheel">
      <mu1 value="1.0"/>
      <mu2 value="1.0"/>
      <kp value="10000000.0"/>
      <kd value="1.0"/>
      <fdir1 value="1 0 0"/>
      <material>Gazebo/Grey</material>
      <turnGravityOff>false</turnGravityOff>
    </gazebo>
    <joint name="back_right_wheel_joint" type="continuous">
      <parent link="base_link"/>
      <child link="back_right_wheel"/>
      <origin rpy="0 0 0" xyz="-.11 0.16 0.0"/>
      <axis rpy="0  0" xyz="0 1 0"/>
      <limit effort="100" velocity="100"/>
      <joint_properties damping="0.0" friction="0.0"/>
    </joint>
    <!-- Mesh wheel -->
    <link name="back_right_wheel1">
        <visual>
            <origin rpy="0 0 3.14" xyz="-.001 0 -.047"/>
          <geometry>
              <mesh filename="${wheel_mesh_path}" scale="${wheel_mesh_scale} ${wheel_mesh_scale} ${wheel_mesh_scale}"/>
          </geometry>
          <material name="DarkGray"/>
        </visual>
        <collision>
            <origin rpy="0 0 3.14" xyz="-.001 0 -.047"/>
          <geometry>
              <mesh filename="${wheel_mesh_path}" scale="${wheel_mesh_scale} ${wheel_mesh_scale} ${wheel_mesh_scale}"/>
          </geometry>
        </collision>
        <inertial>
          <mass value="2"/>
          <origin xyz="0 0 0"/>
          <inertia ixx="0.00108333333333" ixy="0" ixz="0" iyy="0.00108333333333" iyz="0" izz="0.002"/>
        </inertial>
      </link>

      <gazebo reference="back_right_wheel">
        <mu1 value="1.0"/>
        <mu2 value="1.0"/>
        <kp value="10000000.0"/>
        <kd value="1.0"/>
        <fdir1 value="1 0 0"/>
        <material>Gazebo/Grey</material>
        <turnGravityOff>false</turnGravityOff>
      </gazebo>
      <joint name="back_right_wheel1_joint" type="fixed">
        <parent link="back_right_wheel"/>
        <child link="back_right_wheel1"/>
      </joint>

    <!-- Transmission is important to link the joints and the controller -->
    <transmission name="back_right_wheel_joint_trans">
      <type>transmission_interface/SimpleTransmission</type>
      <joint name="back_right_wheel_joint">
          <hardwareInterface>hardware_interface/VelocityJointInterface</hardwareInterface>
        </joint>
      <actuator name="back_right_wheel_joint_motor">
        <hardwareInterface>EffortJointInterface</hardwareInterface>
        <mechanicalReduction>1</mechanicalReduction>
      </actuator>
    </transmission>

  <!--fb : front, back ; lr: left, right -->
  <link name="front_left_wheel">
    <visual>
      <origin rpy="${wheel_rotation} 0  0 " xyz="0 0 0"/>
      <geometry>
        <cylinder length="${wheel_length}" radius="${wheel_radius}"/>
      </geometry>
      <material name="DarkGray"/>
    </visual>
    <collision>
      <origin rpy="${wheel_rotation} 0 0 " xyz="0 0 0"/>
      <geometry>
        <cylinder length="${wheel_length}" radius="${wheel_radius}"/>
      </geometry>
    </collision>
    <inertial>
      <mass value="2"/>
      <origin xyz="0 0 0"/>
      <inertia ixx="0.00108333333333" ixy="0" ixz="0" iyy="0.00108333333333" iyz="0" izz="0.002"/>
    </inertial>
  </link>
  <gazebo reference="front_left_wheel">
    <mu1 value="1.0"/>
    <mu2 value="1.0"/>
    <kp value="10000000.0"/>
    <kd value="1.0"/>
    <fdir1 value="1 0 0"/>
    <material>Gazebo/Grey</material>
    <turnGravityOff>false</turnGravityOff>
  </gazebo>
  <joint name="front_left_wheel_joint" type="continuous">
    <parent link="base_link"/>
    <child link="front_left_wheel"/>
    <origin rpy="0 0 0" xyz=".11 -0.16 0.0"/>
    <axis rpy="0  0" xyz="0 1 0"/>
    <limit effort="100" velocity="100"/>
    <joint_properties damping="0.0" friction="0.0"/>
  </joint>

  <!-- Mesh front wheel -->
  <link name="front_left_wheel1">
      <visual>
          <origin rpy="0 0 0" xyz="-.001 0 -.047"/>
        <geometry>
            <mesh filename="${wheel_mesh_path}" scale="${wheel_mesh_scale} ${wheel_mesh_scale} ${wheel_mesh_scale}"/>
        </geometry>
        <material name="DarkGray"/>
      </visual>
      <collision>
          <origin rpy="0 0 0" xyz="-.001 0 -.047"/>
        <geometry>
            <mesh filename="${wheel_mesh_path}" scale="${wheel_mesh_scale} ${wheel_mesh_scale} ${wheel_mesh_scale}"/>
        </geometry>
      </collision>
      <inertial>
        <mass value="2"/>
        <origin xyz="0 0 0"/>
        <inertia ixx="0.00108333333333" ixy="0" ixz="0" iyy="0.00108333333333" iyz="0" izz="0.002"/>
      </inertial>
    </link>
    <gazebo reference="front_left_wheel">
      <mu1 value="1.0"/>
      <mu2 value="1.0"/>
      <kp value="10000000.0"/>
      <kd value="1.0"/>
      <fdir1 value="1 0 0"/>
      <material>Gazebo/Grey</material>
      <turnGravityOff>false</turnGravityOff>
    </gazebo>
    <joint name="front_left_wheel1_joint" type="fixed">
      <parent link="front_left_wheel"/>
      <child link="front_left_wheel1"/>
    </joint>
  

  <!-- Transmission is important to link the joints and the controller -->
  <transmission name="front_left_wheel_joint_trans">
    <type>transmission_interface/SimpleTransmission</type>
    <joint name="front_left_wheel_joint">
      <hardwareInterface>hardware_interface/VelocityJointInterface</hardwareInterface>
    </joint>
    <actuator name="front_left_wheel_joint_motor">
      <hardwareInterface>EffortJointInterface</hardwareInterface>
      <mechanicalReduction>1</mechanicalReduction>
    </actuator>
  </transmission>

    <!--fb : front, back ; lr: left, right -->
    <link name="back_left_wheel">
      <visual>
        <origin rpy="${wheel_rotation} 0  0 " xyz="0 0 0"/>
        <geometry>
          <cylinder length="${wheel_length}" radius="${wheel_radius}"/>
        </geometry>
        <material name="DarkGray"/>
      </visual>
      <collision>
        <origin rpy="${wheel_rotation} 0 0 " xyz="0 0 0"/>
        <geometry>
          <cylinder length="${wheel_length}" radius="${wheel_radius}"/>
        </geometry>
      </collision>
      <inertial>
        <mass value="2"/>
        <origin xyz="0 0 0"/>
        <inertia ixx="0.00108333333333" ixy="0" ixz="0" iyy="0.00108333333333" iyz="0" izz="0.002"/>
      </inertial>
    </link>
    <gazebo reference="back_left_wheel">
      <mu1 value="1.0"/>
      <mu2 value="1.0"/>
      <kp value="10000000.0"/>
      <kd value="1.0"/>
      <fdir1 value="1 0 0"/>
      <material>Gazebo/Grey</material>
      <turnGravityOff>false</turnGravityOff>
    </gazebo>
    <joint name="back_left_wheel_joint" type="continuous">
      <parent link="base_link"/>
      <child link="back_left_wheel"/>
      <origin rpy="0 0 0" xyz="-.11 -0.16 0.0"/>
      <axis rpy="0  0" xyz="0 1 0"/>
      <limit effort="100" velocity="100"/>
      <joint_properties damping="0.0" friction="0.0"/>
    </joint>

    <!-- Mesh back left wheel -->
    <link name="back_left_wheel1">
        <visual>
            <origin rpy="0 0 0" xyz="-.001 0 -.047"/>
          <geometry>
              <mesh filename="${wheel_mesh_path}" scale="${wheel_mesh_scale} ${wheel_mesh_scale} ${wheel_mesh_scale}"/>
          </geometry>
          <material name="DarkGray"/>
        </visual>
        <collision>
            <origin rpy="0 0 0" xyz="-.001 0 -.047"/>
          <geometry>
              <mesh filename="${wheel_mesh_path}" scale="${wheel_mesh_scale} ${wheel_mesh_scale} ${wheel_mesh_scale}"/>
          </geometry>
        </collision>
        <inertial>
          <mass value="2"/>
          <origin xyz="0 0 0"/>
          <inertia ixx="0.00108333333333" ixy="0" ixz="0" iyy="0.00108333333333" iyz="0" izz="0.002"/>
        </inertial>
      </link>
      <gazebo reference="back_left_wheel">
        <mu1 value="1.0"/>
        <mu2 value="1.0"/>
        <kp value="10000000.0"/>
        <kd value="1.0"/>
        <fdir1 value="1 0 0"/>
        <material>Gazebo/Grey</material>
        <turnGravityOff>false</turnGravityOff>
      </gazebo>
      <joint name="back_left_wheel1_joint" type="fixed">
        <parent link="back_left_wheel"/>
        <child link="back_left_wheel1"/>
      </joint>



    <!-- Transmission is important to link the joints and the controller -->
    <transmission name="back_left_wheel_joint_trans">
      <type>transmission_interface/SimpleTransmission</type>
      <joint name="back_left_wheel_joint">
        <hardwareInterface>hardware_interface/VelocityJointInterface</hardwareInterface>
      </joint>
      <actuator name="back_left_wheel_joint_motor">
        <hardwareInterface>EffortJointInterface</hardwareInterface>
        <mechanicalReduction>1</mechanicalReduction>
      </actuator>
    </transmission>

        <!-- Chasis stand link -->
        <xacro:property name="stand_radius" value="0.01"/>
        <xacro:property name="stand_length" value="0.09"/>
        <link name="stand_front_left">
          <inertial>
            <mass value="5"/>
            <origin xyz="0 0 0"/>
            <!--The 3x3 rotational inertia matrix. -->
            <inertia ixx="0.0282916666667" ixy="0" ixz="0" iyy="0.0282916666667" iyz="0" izz="0.05625"/>
          </inertial>
          <visual>
            <geometry>
              <cylinder radius="${stand_radius}" length="${stand_length}"/>
            </geometry>				
            <origin xyz=".17 .11 .04"/>
            <material name="White"/>
          </visual>
          <collision>
            <origin xyz=".17 .11 .04"/>
            <geometry>
              <cylinder radius="${stand_radius}" length="${stand_length}"/>
            </geometry>	
          </collision>
        </link>
        <gazebo reference="stand_front_left">
          <material>Gazebo/White</material>
          <turnGravityOff>false</turnGravityOff>
        </gazebo>
  
        <joint name="stand_front_left_joint" type="fixed">
            <parent link="base_link"/>
            <child link="stand_front_left"/>
        </joint>

        <!-- Stand back left -->
        <link name="stand_back_left">
          <inertial>
            <mass value="5"/>
            <origin xyz="0 0 0"/>
            <!--The 3x3 rotational inertia matrix. -->
            <inertia ixx="0.0282916666667" ixy="0" ixz="0" iyy="0.0282916666667" iyz="0" izz="0.05625"/>
          </inertial>
          <visual>
            <geometry>
              <cylinder radius="${stand_radius}" length="${stand_length}"/>
            </geometry>				
            <origin xyz="-.17 .11 .05"/>
            <material name="White"/>
          </visual>
          <collision>
            <origin xyz="-.17 .11 .05"/>
            <geometry>
              <cylinder radius="${stand_radius}" length="${stand_length}"/>
            </geometry>	
          </collision>
        </link>
        <gazebo reference="stand_back_left">
          <material>Gazebo/White</material>
          <turnGravityOff>false</turnGravityOff>
        </gazebo>
  
        <joint name="stand_back_left_joint" type="fixed">
            <parent link="base_link"/>
            <child link="stand_back_left"/>
        </joint>

        <!-- Front right stand -->
        <link name="stand_front_right">
          <inertial>
            <mass value="5"/>
            <origin xyz="0 0 0"/>
            <!--The 3x3 rotational inertia matrix. -->
            <inertia ixx="0.0282916666667" ixy="0" ixz="0" iyy="0.0282916666667" iyz="0" izz="0.05625"/>
          </inertial>
          <visual>
            <geometry>
              <cylinder radius="${stand_radius}" length="${stand_length}"/>
            </geometry>				
            <origin xyz=".17 -.11 .04"/>
            <material name="White"/>
          </visual>
          <collision>
            <origin xyz=".17 -.11 .04"/>
            <geometry>
              <cylinder radius="${stand_radius}" length="${stand_length}"/>
            </geometry>	
          </collision>
        </link>
        <gazebo reference="stand_front_right">
          <material>Gazebo/White</material>
          <turnGravityOff>false</turnGravityOff>
        </gazebo>
  
        <joint name="stand_front_right_joint" type="fixed">
            <parent link="base_link"/>
            <child link="stand_front_right"/>
        </joint>

        <!-- Back right stand -->
        <link name="stand_back_right">
          <inertial>
            <mass value="5"/>
            <origin xyz="0 0 0"/>
            <!--The 3x3 rotational inertia matrix. -->
            <inertia ixx="0.0282916666667" ixy="0" ixz="0" iyy="0.0282916666667" iyz="0" izz="0.05625"/>
          </inertial>
          <visual>
            <geometry>
              <cylinder radius="${stand_radius}" length="${stand_length}"/>
            </geometry>				
            <origin xyz="-.17 -.11 .05"/>
            <material name="White"/>
          </visual>
          <collision>
            <origin xyz="-.17 -.11 .05"/>
            <geometry>
              <cylinder radius="${stand_radius}" length="${stand_length}"/>
            </geometry>	
          </collision>
        </link>
        <gazebo reference="stand_back_right">
          <material>Gazebo/White</material>
          <turnGravityOff>false</turnGravityOff>
        </gazebo>
  
        <joint name="stand_back_right_joint" type="fixed">
            <parent link="base_link"/>
            <child link="stand_back_right"/>
        </joint>

    <!-- Bumper link -->
    <xacro:property name="bumper_mesh_path" value="package://sphinx_description/meshes/bumper.dae"/>
    <xacro:property name="bumper_mesh_scale" value=".17"/>
    
    <link name="bumper">
      <visual>
        <geometry>
          <mesh filename="${bumper_mesh_path}" scale="${bumper_mesh_scale} ${bumper_mesh_scale} ${bumper_mesh_scale}"/>
        </geometry>	
        <origin xyz="0 0 0" rpy="0 0 1.55"/>
      </visual>
      <collision>
        <geometry>
          <mesh filename="${bumper_mesh_path}" scale="${bumper_mesh_scale} ${bumper_mesh_scale} ${bumper_mesh_scale}"/>
        </geometry>				
      </collision>
    <inertial>
        <mass value=".1"/>
      <inertia ixx="-0.002903" ixy="-0.006721" ixz="0.999973" iyy="-0.073394" iyz="0.002401" izy="0.997280" izz="0.006916"/>
      </inertial>
    </link>
  
    <joint name="bumper_joint" type="fixed">
      <parent link="base_link"/>
      <child link="bumper"/>
      <origin xyz=".22 .060 -.01" rpy="0 0 0"/>
    </joint>

    <!-- ROOF link -->
    <link name="roof_link">
        <inertial>
          <mass value="5"/>
          <origin xyz="0 0 0"/>
          <!--The 3x3 rotational inertia matrix. -->
          <inertia ixx="0.0282916666667" ixy="0" ixz="0" iyy="0.0282916666667" iyz="0" izz="0.05625"/>
        </inertial>
        <visual>
          <origin rpy="0 0 0" xyz="0 0 0"/>
          <geometry>
            <box size="0.4 0.2 0.005"/>
          </geometry>
          <material name="White"/>
        </visual>
        <collision>
          <origin rpy="0 0 0 " xyz="0 0 0"/>
          <geometry>
              <box size="0.4 0.2 0.005"/>
          </geometry>
        </collision>
      </link>
      <gazebo reference="roof_link">
        <material>Gazebo/White</material>
        <turnGravityOff>false</turnGravityOff>
      </gazebo>

      <joint name="roof_joint" type="fixed">
          <parent link="base_link"/>
          <child link="roof_link"/>
          <origin xyz="0 0 .08" rpy="0 0 0"/>
        </joint>

      <!-- Mesh ROOF link -->
      <xacro:property name="roof_mesh_path" value="package://sphinx_description/meshes/roof.dae"/>
      <xacro:property name="roof_mesh_scale" value=".065"/>
      <link name="roof_mesh_link">
          <inertial>
            <mass value="5"/>
            <origin xyz="0 0 0"/>
            <!--The 3x3 rotational inertia matrix. -->
            <inertia ixx="0.0282916666667" ixy="0" ixz="0" iyy="0.0282916666667" iyz="0" izz="0.05625"/>
          </inertial>
          <visual>
            <origin rpy="0 0 -1.57" xyz="-.22 .14 .003"/>
            <geometry>
                <mesh filename="${roof_mesh_path}" scale="${roof_mesh_scale} ${roof_mesh_scale} ${roof_mesh_scale}"/>
            </geometry>
          </visual>
          <collision>
              <origin rpy="0 0 -1.57" xyz="-.22 .14 .003"/>
            <geometry>
                <mesh filename="${roof_mesh_path}" scale="${roof_mesh_scale} ${roof_mesh_scale} ${roof_mesh_scale}"/>
            </geometry>
          </collision>
        </link>
        <gazebo reference="roof_link">
          <turnGravityOff>false</turnGravityOff>
        </gazebo>

        <joint name="roof_mesh_joint" type="fixed">
            <parent link="roof_link"/>
            <child link="roof_mesh_link"/>
          </joint>
</robot>